Workbook

Sheet Orders
A1: Row ID | B1: Order ID | C1: Order Date | D1: Ship Date | E1: Ship Mode | F1: Customer ID | G1: Customer Name | H1: Segment | I1: Country/Region | J1: City | K1: State | L1: Postal Code | M1: Region | N1: Sales Manager | O1: Product ID | P1: Category | Q1: Sub-Category | R1: Product Name | S1: Sales | T1: Quantity | U1: Discount | V1: Profit
A2: 1 | B2: CA-2018-152156 | C2: 43412 | D2: 43415 | E2: Second Class | F2: CG-12520 | G2: Claire Gute | H2: Consumer | I2: United States | J2: Henderson | K2: Kentucky | L2: 42420 | M2: South | N2: =VLOOKUP(M2,People!$A$1:$C$5,2,0) -> Cassandra Brandow | O2: FUR-BO-10001798 | P2: Furniture | Q2: Bookcases | R2: Bush Somerset Collection Bookcase | S2: 261.96 | T2: 2 | U2: 0 | V2: 41.9136
A3: 2 | B3: CA-2018-152156 | C3: 43412 | D3: 43415 | E3: Second Class | F3: CG-12520 | G3: Claire Gute | H3: Consumer | I3: United States | J3: Henderson | K3: Kentucky | L3: 42420 | M3: South | N3: =VLOOKUP(M3,People!$A$1:$C$5,2,0) -> Cassandra Brandow | O3: FUR-CH-10000454 | P3: Furniture | Q3: Chairs | R3: Hon Deluxe Fabric Upholstered Stacking Chairs, Rounded Back | S3: 731.94 | T3: 3 | U3: 0 | V3: 219.582 | Z3: =SUMIFS(V:V,P:P,"Furniture",M:M,"South") -> 6771.2061
A4: 3 | B4: CA-2018-138688 | C4: 43263 | D4: 43267 | E4: Second Class | F4: DV-13045 | G4: Darrin Van Huff | H4: Corporate | I4: United States | J4: Los Angeles | K4: California | L4: 90036 | M4: West | N4: =VLOOKUP(M4,People!$A$1:$C$5,2,0) -> Anna Andreadi | O4: OFF-LA-10000240 | P4: Office Supplies | Q4: Labels | R4: Self-Adhesive Address Labels for Typewriters by Universal | S4: 14.62 | T4: 2 | U4: 0 | V4: 6.8714
A5: 4 | B5: US-2017-108966 | C5: 43019 | D5: 43026 | E5: Standard Class | F5: SO-20335 | G5: Sean O'Donnell | H5: Consumer | I5: United States | J5: Fort Lauderdale | K5: Florida | L5: 33311 | M5: South | N5: =VLOOKUP(M5,People!$A$1:$C$5,2,0) -> Cassandra Brandow | O5: FUR-TA-10000577 | P5: Furniture | Q5: Tables | R5: Bretford CR4500 Series Slim Rectangular Table | S5: 957.5775 | T5: 5 | U5: 0.45 | V5: -383.031 | Z5: =AVERAGEIFS(U:U,P:P,"Furniture",M:M, "South") -> 0.12153614
A6: 5 | B6: US-2017-108966 | C6: 43019 | D6: 43026 | E6: Standard Class | F6: SO-20335 | G6: Sean O'Donnell | H6: Consumer | I6: United States | J6: Fort Lauderdale | K6: Florida | L6: 33311 | M6: South | N6: =VLOOKUP(M6,People!$A$1:$C$5,2,0) -> Cassandra Brandow | O6: OFF-ST-10000760 | P6: Office Supplies | Q6: Storage | R6: Eldon Fold 'N Roll Cart System | S6: 22.368 | T6: 2 | U6: 0.2 | V6: 2.5164
A7: 6 | B7: CA-2016-115812 | C7: 42530 | D7: 42535 | E7: Standard Class | F7: BH-11710 | G7: Brosina Hoffman | H7: Consumer | I7: United States | J7: Los Angeles | K7: California | L7: 90032 | M7: West | N7: =VLOOKUP(M7,People!$A$1:$C$5,2,0) -> Anna Andreadi | O7: FUR-FU-10001487 | P7: Furniture | Q7: Furnishings | R7: Eldon Expressions Wood and Plastic Desk Accessories, Cherry Wood | S7: 48.86 | T7: 7 | U7: 0 | V7: 14.1694
A8: 7 | B8: CA-2016-115812 | C8: 42530 | D8: 42535 | E8: Standard Class | F8: BH-11710 | G8: Brosina Hoffman | H8: Consumer | I8: United States | J8: Los Angeles | K8: California | L8: 90032 | M8: West | N8: =VLOOKUP(M8,People!$A$1:$C$5,2,0) -> Anna Andreadi | O8: OFF-AR-10002833 | P8: Office Supplies | Q8: Art | R8: Newell 322 | S8: 7.28 | T8: 4 | U8: 0 | V8: 1.9656
A9: 8 | B9: CA-2016-115812 | C9: 42530 | D9: 42535 | E9: Standard Class | F9: BH-11710 | G9: Brosina Hoffman | H9: Consumer | I9: United States | J9: Los Angeles | K9: California | L9: 90032 | M9: West | N9: =VLOOKUP(M9,People!$A$1:$C$5,2,0) -> Anna Andreadi | O9: TEC-PH-10002275 | P9: Technology | Q9: Phones | R9: Mitel 5320 IP Phone VoIP phone | S9: 907.152 | T9: 6 | U9: 0.2 | V9: 90.7152
A10: 9 | B10: CA-2016-115812 | C10: 42530 | D10: 42535 | E10: Standard Class | F10: BH-11710 | G10: Brosina Hoffman | H10: Consumer | I10: United States | J10: Los Angeles | K10: California | L10: 90032 | M10: West | N10: =VLOOKUP(M10,People!$A$1:$C$5,2,0) -> Anna Andreadi | O10: OFF-BI-10003910 | P10: Office Supplies | Q10: Binders | R10: DXL Angle-View Binders with Locking Rings by Samsill | S10: 18.504 | T10: 3 | U10: 0.2 | V10: 5.7825
A11: 10 | B11: CA-2016-115812 | C11: 42530 | D11: 42535 | E11: Standard Class | F11: BH-11710 | G11: Brosina Hoffman | H11: Consumer | I11: United States | J11: Los Angeles | K11: California | L11: 90032 | M11: West | N11: =VLOOKUP(M11,People!$A$1:$C$5,2,0) -> Anna Andreadi | O11: OFF-AP-10002892 | P11: Office Supplies | Q11: Appliances | R11: Belkin F5C206VTEL 6 Outlet Surge | S11: 114.9 | T11: 5 | U11: 0 | V11: 34.47
A12: 11 | B12: CA-2016-115812 | C12: 42530 | D12: 42535 | E12: Standard Class | F12: BH-11710 | G12: Brosina Hoffman | H12: Consumer | I12: United States | J12: Los Angeles | K12: California | L12: 90032 | M12: West | N12: =VLOOKUP(M12,People!$A$1:$C$5,2,0) -> Anna Andreadi | O12: FUR-TA-10001539 | P12: Furniture | Q12: Tables | R12: Chromcraft Rectangular Conference Tables | S12: 1706.184 | T12: 9 | U12: 0.2 | V12: 85.3092
A13: 12 | B13: CA-2016-115812 | C13: 42530 | D13: 42535 | E13: Standard Class | F13: BH-11710 | G13: Brosina Hoffman | H13: Consumer | I13: United States | J13: Los Angeles | K13: California | L13: 90032 | M13: West | N13: =VLOOKUP(M13,People!$A$1:$C$5,2,0) -> Anna Andreadi | O13: TEC-PH-10002033 | P13: Technology | Q13: Phones | R13: Konftel 250 Conference phone - Charcoal black | S13: 911.424 | T13: 4 | U13: 0.2 | V13: 68.3568
A14: 13 | B14: CA-2019-114412 | C14: 43570 | D14: 43575 | E14: Standard Class | F14: AA-10480 | G14: Andrew Allen | H14: Consumer | I14: United States | J14: Concord | K14: North Carolina | L14: 28027 | M14: South | N14: =VLOOKUP(M14,People!$A$1:$C$5,2,0) -> Cassandra Brandow | O14: OFF-PA-10002365 | P14: Office Supplies | Q14: Paper | R14: Xerox 1967 | S14: 15.552 | T14: 3 | U14: 0.2 | V14: 5.4432
A15: 14 | B15: CA-2018-161389 | C15: 43439 | D15: 43444 | E15: Standard Class | F15: IM-15070 | G15: Irene Maddox | H15: Consumer | I15: United States | J15: Seattle | K15: Washington | L15: 98103 | M15: West | N15: =VLOOKUP(M15,People!$A$1:$C$5,2,0) -> Anna Andreadi | O15: OFF-BI-10003656 | P15: Office Supplies | Q15: Binders | R15: Fellowes PB200 Plastic Comb Binding Machine | S15: 407.976 | T15: 3 | U15: 0.2 | V15: 132.5922
A16: 15 | B16: US-2017-118983 | C16: 43061 | D16: 43065 | E16: Standard Class | F16: HP-14815 | G16: Harold Pawlan | H16: Home Office | I16: United States | J16: Fort Worth | K16: Texas | L16: 76106 | M16: Central | N16: =VLOOKUP(M16,People!$A$1:$C$5,2,0) -> Kelly Williams | O16: OFF-AP-10002311 | P16: Office Supplies | Q16: Appliances | R16: Holmes Replacement Filter for HEPA Air Cleaner, Very Large Room, HEPA Filter | S16: 68.81 | T16: 5 | U16: 0.8 | V16: -123.858
A17: 16 | B17: US-2017-118983 | C17: 43061 | D17: 43065 | E17: Standard Class | F17: HP-14815 | G17: Harold Pawlan | H17: Home Office | I17: United States | J17: Fort Worth | K17: Texas | L17: 76106 | M17: Central | N17: =VLOOKUP(M17,People!$A$1:$C$5,2,0) -> Kelly Williams | O17: OFF-BI-10000756 | P17: Office Supplies | Q17: Binders | R17: Storex DuraTech Recycled Plastic Frosted Binders | S17: 2.544 | T17: 3 | U17: 0.8 | V17: -3.816
... A2235: 2234 | B2235: CA-2017-123232 | C2235: 43083 | D2235: 43085 | E2235: Second Class | F2235: DJ-13630 | G2235: Doug Jacobs | H2235: Consumer | I2235: United States | J2235: Portland | K2235: Oregon | L2235: 97206 | M2235: West | N2235: =VLOOKUP(M2235,People!$A$1:$C$5,2,0) -> Anna Andreadi | O2235: TEC-PH-10001051 | P2235: Technology | Q2235: Phones | R2235: HTC One | S2235: 319.968 | T2235: 4 | U2235: 0.2 | V2235: 35.9964
A2236: 2235 | B2236: CA-2019-104066 | C2236: 43804 | D2236: 43809 | E2236: Standard Class | F2236: QJ-19255 | G2236: Quincy Jones | H2236: Corporate | I2236: United States | J2236: Burlington | K2236: Vermont | M2236: East | N2236: =VLOOKUP(M2236,People!$A$1:$C$5,2,0) -> Chuck Magee | O2236: TEC-AC-10001013 | P2236: Technology | Q2236: Accessories | R2236: Logitech ClearChat Comfort/USB Headset H390 | S2236: 205.03 | T2236: 7 | U2236: 0 | V2236: 67.6599
A2237: 2236 | B2237: CA-2017-145849 | C2237: 42993 | D2237: 42995 | E2237: Second Class | F2237: CT-11995 | G2237: Carol Triggs | H2237: Consumer | I2237: United States | J2237: Indianapolis | K2237: Indiana | L2237: 46203 | M2237: Central | N2237: =VLOOKUP(M2237,People!$A$1:$C$5,2,0) -> Kelly Williams | O2237: OFF-ST-10000025 | P2237: Office Supplies | Q2237: Storage | R2237: Fellowes Stor/Drawer Steel Plus Storage Drawers | S2237: 190.86 | T2237: 2 | U2237: 0 | V2237: 11.4516
A2238: 2237 | B2238: CA-2017-145849 | C2238: 42993 | D2238: 42995 | E2238: Second Class | F2238: CT-11995 | G2238: Carol Triggs | H2238: Consumer | I2238: United States | J2238: Indianapolis | K2238: Indiana | L2238: 46203 | M2238: Central | N2238: =VLOOKUP(M2238,People!$A$1:$C$5,2,0) -> Kelly Williams | O2238: OFF-AR-10000817 | P2238: Office Supplies | Q2238: Art | R2238: Manco Dry-Lighter Erasable Highlighter | S2238: 24.32 | T2238: 8 | U2238: 0 | V2238: 8.2688
A2239: 2238 | B2239: CA-2018-122322 | C2239: 43296 | D2239: 43302 | E2239: Standard Class | F2239: RH-19510 | G2239: Rick Huthwaite | H2239: Home Office | I2239: United States | J2239: Provo | K2239: Utah | L2239: 84604 | M2239: West | N2239: =VLOOKUP(M2239,People!$A$1:$C$5,2,0) -> Anna Andreadi | O2239: OFF-SU-10000952 | P2239: Office Supplies | Q2239: Supplies | R2239: Fiskars Home & Office Scissors | S2239: 44.4 | T2239: 5 | U2239: 0 | V2239: 12.432
A2240: 2239 | B2240: CA-2019-166849 | C2240: 43575 | D2240: 43581 | E2240: Standard Class | F2240: SJ-20125 | G2240: Sanjit Jacobs | H2240: Home Office | I2240: United States | J2240: Chicago | K2240: Illinois | L2240: 60610 | M2240: Central | N2240: =VLOOKUP(M2240,People!$A$1:$C$5,2,0) -> Kelly Williams | O2240: FUR-FU-10004597 | P2240: Furniture | Q2240: Furnishings | R2240: Eldon Cleatmat Chair Mats for Medium Pile Carpets | S2240: 44.4 | T2240: 2 | U2240: 0.6 | V2240: -52.17
A2241: 2240 | B2241: CA-2018-146633 | C2241: 43419 | D2241: 43421 | E2241: Second Class | F2241: TG-21310 | G2241: Toby Gnade | H2241: Consumer | I2241: United States | J2241: Los Angeles | K2241: California | L2241: 90049 | M2241: West | N2241: =VLOOKUP(M2241,People!$A$1:$C$5,2,0) -> Anna Andreadi | O2241: OFF-BI-10003527 | P2241: Office Supplies | Q2241: Binders | R2241: Fellowes PB500 Electric Punch Plastic Comb Binding Machine with Manual Bind | S2241: 1016.792 | T2241: 1 | U2241: 0.2 | V2241: 381.297
A2242: 2241 | B2242: CA-2018-146633 | C2242: 43419 | D2242: 43421 | E2242: Second Class | F2242: TG-21310 | G2242: Toby Gnade | H2242: Consumer | I2242: United States | J2242: Los Angeles | K2242: California | L2242: 90049 | M2242: West | N2242: =VLOOKUP(M2242,People!$A$1:$C$5,2,0) -> Anna Andreadi | O2242: OFF-BI-10002982 | P2242: Office Supplies | Q2242: Binders | R2242: Avery Self-Adhesive Photo Pockets for Polaroid Photos | S2242: 38.136 | T2242: 7 | U2242: 0.2 | V2242: 13.3476
A2243: 2242 | B2243: US-2018-126893 | C2243: 43430 | D2243: 43435 | E2243: Standard Class | F2243: CT-11995 | G2243: Carol Triggs | H2243: Consumer | I2243: United States | J2243: Philadelphia | K2243: Pennsylvania | L2243: 19134 | M2243: East | N2243: =VLOOKUP(M2243,People!$A$1:$C$5,2,0) -> Chuck Magee | O2243: TEC-PH-10004165 | P2243: Technology | Q2243: Phones | R2243: Mitel MiVoice 5330e IP Phone | S2243: 494.982 | T2243: 3 | U2243: 0.4 | V2243: -115.4958
A2244: 2243 | B2244: CA-2019-103380 | C2244: 43790 | D2244: 43794 | E2244: Standard Class | F2244: BF-11005 | G2244: Barry Franz | H2244: Home Office | I2244: United States | J2244: Pasadena | K2244: California | L2244: 91104 | M2244: West | N2244: =VLOOKUP(M2244,People!$A$1:$C$5,2,0) -> Anna Andreadi | O2244: OFF-ST-10003442 | P2244: Office Supplies | Q2244: Storage | R2244: Eldon Portable Mobile Manager | S2244: 56.56 | T2244: 2 | U2244: 0 | V2244: 15.2712
A2245: 2244 | B2245: CA-2019-103380 | C2245: 43790 | D2245: 43794 | E2245: Standard Class | F2245: BF-11005 | G2245: Barry Franz | H2245: Home Office | I2245: United States | J2245: Pasadena | K2245: California | L2245: 91104 | M2245: West | N2245: =VLOOKUP(M2245,People!$A$1:$C$5,2,0) -> Anna Andreadi | O2245: OFF-AR-10003856 | P2245: Office Supplies | Q2245: Art | R2245: Newell 344 | S2245: 5.56 | T2245: 2 | U2245: 0 | V2245: 1.4456
A2246: 2245 | B2246: CA-2019-103380 | C2246: 43790 | D2246: 43794 | E2246: Standard Class | F2246: BF-11005 | G2246: Barry Franz | H2246: Home Office | I2246: United States | J2246: Pasadena | K2246: California | L2246: 91104 | M2246: West | N2246: =VLOOKUP(M2246,People!$A$1:$C$5,2,0) -> Anna Andreadi | O2246: OFF-FA-10004248 | P2246: Office Supplies | Q2246: Fasteners | R2246: Advantus T-Pin Paper Clips | S2246: 9.02 | T2246: 2 | U2246: 0 | V2246: 3.5178
A2247: 2246 | B2247: CA-2019-103380 | C2247: 43790 | D2247: 43794 | E2247: Standard Class | F2247: BF-11005 | G2247: Barry Franz | H2247: Home Office | I2247: United States | J2247: Pasadena | K2247: California | L2247: 91104 | M2247: West | N2247: =VLOOKUP(M2247,People!$A$1:$C$5,2,0) -> Anna Andreadi | O2247: OFF-AP-10001492 | P2247: Office Supplies | Q2247: Appliances | R2247: Acco Six-Outlet Power Strip, 4' Cord Length | S2247: 8.62 | T2247: 1 | U2247: 0 | V2247: 2.2412
A2248: 2247 | B2248: CA-2019-103380 | C2248: 43790 | D2248: 43794 | E2248: Standard Class | F2248: BF-11005 | G2248: Barry Franz | H2248: Home Office | I2248: United States | J2248: Pasadena | K2248: California | L2248: 91104 | M2248: West | N2248: =VLOOKUP(M2248,People!$A$1:$C$5,2,0) -> Anna Andreadi | O2248: TEC-PH-10004165 | P2248: Technology | Q2248: Phones | R2248: Mitel MiVoice 5330e IP Phone | S2248: 659.976 | T2248: 3 | U2248: 0.2 | V2248: 49.4982
... A5275: 5274 | B5275: US-2018-158309 | C5275: 43430 | D5275: 43433 | E5275: First Class | F5275: PA-19060 | G5275: Pete Armstrong | H5275: Home Office | I5275: United States | J5275: Miami | K5275: Florida | L5275: 33142 | M5275: South | N5275: =VLOOKUP(M5275,People!$A$1:$C$5,2,0) -> Cassandra Brandow | O5275: OFF-BI-10000145 | P5275: Office Supplies | Q5275: Binders | R5275: Zipper Ring Binder Pockets | S5275: 3.744 | T5275: 4 | U5275: 0.7 | V5275: -2.6208
A5276: 5275 | B5276: CA-2017-162887 | C5276: 43046 | D5276: 43048 | E5276: Second Class | F5276: SV-20785 | G5276: Stewart Visinsky | H5276: Consumer | I5276: United States | J5276: Burlington | K5276: Vermont | M5276: East | N5276: =VLOOKUP(M5276,People!$A$1:$C$5,2,0) -> Chuck Magee | O5276: FUR-CH-10000595 | P5276: Furniture | Q5276: Chairs | R5276: Safco Contoured Stacking Chairs | S5276: 715.2 | T5276: 3 | U5276: 0 | V5276: 178.8
A5277: 5276 | B5277: CA-2019-147333 | C5277: 43813 | D5277: 43819 | E5277: Standard Class | F5277: KL-16555 | G5277: Kelly Lampkin | H5277: Corporate | I5277: United States | J5277: Fayetteville | K5277: Arkansas | L5277: 72701 | M5277: South | N5277: =VLOOKUP(M5277,People!$A$1:$C$5,2,0) -> Cassandra Brandow | O5277: TEC-AC-10004469 | P5277: Technology | Q5277: Accessories | R5277: Microsoft Sculpt Comfort Mouse | S5277: 159.8 | T5277: 4 | U5277: 0 | V5277: 70.312
A5278: 5277 | B5278: CA-2019-147333 | C5278: 43813 | D5278: 43819 | E5278: Standard Class | F5278: KL-16555 | G5278: Kelly Lampkin | H5278: Corporate | I5278: United States | J5278: Fayetteville | K5278: Arkansas | L5278: 72701 | M5278: South | N5278: =VLOOKUP(M5278,People!$A$1:$C$5,2,0) -> Cassandra Brandow | O5278: TEC-AC-10003038 | P5278: Technology | Q5278: Accessories | R5278: Kingston Digital DataTraveler 16GB USB 2.0 | S5278: 44.75 | T5278: 5 | U5278: 0 | V5278: 8.5025
A5279: 5278 | B5279: CA-2016-113859 | C5279: 42626 | D5279: 42630 | E5279: Standard Class | F5279: BC-11125 | G5279: Becky Castell | H5279: Home Office | I5279: United States | J5279: Odessa | K5279: Texas | L5279: 79762 | M5279: Central | N5279: =VLOOKUP(M5279,People!$A$1:$C$5,2,0) -> Kelly Williams | O5279: FUR-CH-10004698 | P5279: Furniture | Q5279: Chairs | R5279: Padded Folding Chairs, Black, 4/Carton | S5279: 340.116 | T5279: 6 | U5279: 0.3 | V5279: -9.7176
A5280: 5279 | B5280: CA-2016-159681 | C5280: 42711 | D5280: 42717 | E5280: Standard Class | F5280: PO-18850 | G5280: Patrick O'Brill | H5280: Consumer | I5280: United States | J5280: Virginia Beach | K5280: Virginia | L5280: 23464 | M5280: South | N5280: =VLOOKUP(M5280,People!$A$1:$C$5,2,0) -> Cassandra Brandow | O5280: OFF-PA-10003641 | P5280: Office Supplies | Q5280: Paper | R5280: Xerox 1909 | S5280: 105.52 | T5280: 4 | U5280: 0 | V5280: 48.5392
A5281: 5280 | B5281: US-2019-104094 | C5281: 43715 | D5281: 43719 | E5281: Standard Class | F5281: AG-10675 | G5281: Anna Gayman | H5281: Consumer | I5281: United States | J5281: Milwaukee | K5281: Wisconsin | L5281: 53209 | M5281: Central | N5281: =VLOOKUP(M5281,People!$A$1:$C$5,2,0) -> Kelly Williams | O5281: TEC-AC-10002134 | P5281: Technology | Q5281: Accessories | R5281: Rosewill 107 Normal Keys USB Wired Standard Keyboard | S5281: 13.48 | T5281: 1 | U5281: 0 | V5281: 1.8872
A5282: 5281 | B5282: CA-2019-152709 | C5282: 43745 | D5282: 43750 | E5282: Standard Class | F5282: DB-13210 | G5282: Dean Braden | H5282: Consumer | I5282: United States | J5282: Detroit | K5282: Michigan | L5282: 48234 | M5282: Central | N5282: =VLOOKUP(M5282,People!$A$1:$C$5,2,0) -> Kelly Williams | O5282: OFF-ST-10001837 | P5282: Office Supplies | Q5282: Storage | R5282: SAFCO Mobile Desk Side File, Wire Frame | S5282: 85.52 | T5282: 2 | U5282: 0 | V5282: 22.2352
A5283: 5282 | B5283: CA-2017-105158 | C5283: 42983 | D5283: 42988 | E5283: Standard Class | F5283: SP-20860 | G5283: Sung Pak | H5283: Corporate | I5283: United States | J5283: Rochester | K5283: Minnesota | L5283: 55901 | M5283: Central | N5283: =VLOOKUP(M5283,People!$A$1:$C$5,2,0) -> Kelly Williams | O5283: FUR-FU-10001706 | P5283: Furniture | Q5283: Furnishings | R5283: Longer-Life Soft White Bulbs | S5283: 6.16 | T5283: 2 | U5283: 0 | V5283: 2.9568
...

Sheet People
A1: Region | B1: Sales Manager
A2: West | B2: Anna Andreadi
A3: East | B3: Chuck Magee
A4: Central | B4: Kelly Williams
A5: South | B5: Cassandra Brandow

Sheet Returns
A1: Returned | B1: Order ID
A2: Yes | B2: CA-2016-100762
A3: Yes | B3: CA-2016-100762
A4: Yes | B4: CA-2016-100762
A5: Yes | B5: CA-2016-100762
A6: Yes | B6: CA-2016-100867
A7: Yes | B7: CA-2016-102652
A8: Yes | B8: CA-2016-102652
A9: Yes | B9: CA-2016-102652
A10: Yes | B10: CA-2016-102652
A11: Yes | B11: CA-2016-103373
A12: Yes | B12: CA-2016-103744
... A801: Yes | B801: US-2019-155999
